Workbook

Sheet Portfolio
A1: ID | B1: Company Name | C1: Purchase Date | D1: Owner | E1: Type | F1: Stock Name | G1: Is USD | H1: Qty | I1: Buy Price | J1: AUD > US exc. | K1: AUD Price | L1: US Price
A2: AAPL_1 | B2: Apple Inc. | C2: 44116 | D2: Gabriel | E2: Stock | F2: AAPL | G2: Yes | H2: 83.4307 | I2: 119.86 | J2: =IFERROR(INDEX(Rates!$B:$B,MATCH(C2,Rates!$A:$A,0)),"N/A") -> 0.72134 | K2: =IF(Holdings[[#This Row],[Is USD]]="No",Holdings[[#This Row],[Buy Price]]*Holdings[[#This Row],[Qty]],Holdings[[#This Row],[US Price]]/Holdings[[#This Row],[AUD > US exc.]]) -> 13863.093 | L2: =IF(Holdings[[#This Row],[Is USD]]="Yes",Holdings[[#This Row],[Buy Price]]*Holdings[[#This Row],[Qty]],"") -> 10000.004
A3: AMZN_1 | B3: Amazon.com Inc. | C3: 44350 | D3: Arina | E3: Stock | F3: AMZN | G3: Yes | H3: 20 | I3: 160 | J3: =IFERROR(INDEX(Rates!$B:$B,MATCH(C3,Rates!$A:$A,0)),"N/A") -> 0.77172 | K3: =IF(Holdings[[#This Row],[Is USD]]="No",Holdings[[#This Row],[Buy Price]]*Holdings[[#This Row],[Qty]],Holdings[[#This Row],[US Price]]/Holdings[[#This Row],[AUD > US exc.]]) -> 4146.5817 | L3: =IF(Holdings[[#This Row],[Is USD]]="Yes",Holdings[[#This Row],[Buy Price]]*Holdings[[#This Row],[Qty]],"") -> 3200
A4: AMZN_2 | B4: Amazon.com Inc. | C4: 44116 | D4: Gabriel | E4: Stock | F4: AMZN | G4: Yes | H4: 63.36 | I4: 157.83 | J4: =IFERROR(INDEX(Rates!$B:$B,MATCH(C4,Rates!$A:$A,0)),"N/A") -> 0.72134 | K4: =IF(Holdings[[#This Row],[Is USD]]="No",Holdings[[#This Row],[Buy Price]]*Holdings[[#This Row],[Qty]],Holdings[[#This Row],[US Price]]/Holdings[[#This Row],[AUD > US exc.]]) -> 13863.239 | L4: =IF(Holdings[[#This Row],[Is USD]]="Yes",Holdings[[#This Row],[Buy Price]]*Holdings[[#This Row],[Qty]],"") -> 10000.109
A5: ARKK_1 | B5: ARK Innovation ETF | C5: 44300 | D5: Arina | E5: Stock | F5: ARKK | G5: Yes | H5: 31.176929 | I5: 128.3 | J5: =IFERROR(INDEX(Rates!$B:$B,MATCH(C5,Rates!$A:$A,0)),"N/A") -> 0.76885 | K5: =IF(Holdings[[#This Row],[Is USD]]="No",Holdings[[#This Row],[Buy Price]]*Holdings[[#This Row],[Qty]],Holdings[[#This Row],[US Price]]/Holdings[[#This Row],[AUD > US exc.]]) -> 5202.5753 | L5: =IF(Holdings[[#This Row],[Is USD]]="Yes",Holdings[[#This Row],[Buy Price]]*Holdings[[#This Row],[Qty]],"") -> 4000
A6: ASX:NDQ_1 | B6: BetaShares NASDAQ 100 ETF | C6: 44322 | D6: Arina | E6: Stock | F6: ASX:NDQ | G6: No | H6: 233 | I6: 28.9 | J6: =IFERROR(INDEX(Rates!$B:$B,MATCH(C6,Rates!$A:$A,0)),"N/A") -> 0.77571 | K6: =IF(Holdings[[#This Row],[Is USD]]="No",Holdings[[#This Row],[Buy Price]]*Holdings[[#This Row],[Qty]],Holdings[[#This Row],[US Price]]/Holdings[[#This Row],[AUD > US exc.]]) -> 6733.7 | L6: =IF(Holdings[[#This Row],[Is USD]]="Yes",Holdings[[#This Row],[Buy Price]]*Holdings[[#This Row],[Qty]],"")
A7: ASX:NDQ_2 | B7: BetaShares NASDAQ 100 ETF | C7: 44204 | D7: Gabriel | E7: Stock | F7: ASX:NDQ | G7: No | H7: 258 | I7: 27.6 | J7: =IFERROR(INDEX(Rates!$B:$B,MATCH(C7,Rates!$A:$A,0)),"N/A") -> 0.77738 | K7: =IF(Holdings[[#This Row],[Is USD]]="No",Holdings[[#This Row],[Buy Price]]*Holdings[[#This Row],[Qty]],Holdings[[#This Row],[US Price]]/Holdings[[#This Row],[AUD > US exc.]]) -> 7120.8 | L7: =IF(Holdings[[#This Row],[Is USD]]="Yes",Holdings[[#This Row],[Buy Price]]*Holdings[[#This Row],[Qty]],"")
A8: ASX:VAS_1 | B8: Vanguard Australian Shares Index ETF | C8: 44204 | D8: Gabriel | E8: Stock | F8: ASX:VAS | G8: No | H8: 178 | I8: 85.91 | J8: =IFERROR(INDEX(Rates!$B:$B,MATCH(C8,Rates!$A:$A,0)),"N/A") -> 0.77738 | K8: =IF(Holdings[[#This Row],[Is USD]]="No",Holdings[[#This Row],[Buy Price]]*Holdings[[#This Row],[Qty]],Holdings[[#This Row],[US Price]]/Holdings[[#This Row],[AUD > US exc.]]) -> 15291.98 | L8: =IF(Holdings[[#This Row],[Is USD]]="Yes",Holdings[[#This Row],[Buy Price]]*Holdings[[#This Row],[Qty]],"")
A9: ASX:VEU_1 | B9: Vanguard All-World ex-US Shares Index ETF | C9: 44322 | D9: Arina | E9: Stock | F9: ASX:VEU | G9: No | H9: 48 | I9: 80.92 | J9: =IFERROR(INDEX(Rates!$B:$B,MATCH(C9,Rates!$A:$A,0)),"N/A") -> 0.77571 | K9: =IF(Holdings[[#This Row],[Is USD]]="No",Holdings[[#This Row],[Buy Price]]*Holdings[[#This Row],[Qty]],Holdings[[#This Row],[US Price]]/Holdings[[#This Row],[AUD > US exc.]]) -> 3884.16 | L9: =IF(Holdings[[#This Row],[Is USD]]="Yes",Holdings[[#This Row],[Buy Price]]*Holdings[[#This Row],[Qty]],"")
A10: ASX:VEU_2 | B10: Vanguard All-World ex-US Shares Index ETF | C10: 44204 | D10: Gabriel | E10: Stock | F10: ASX:VEU | G10: No | H10: 125 | I10: 77.45 | J10: =IFERROR(INDEX(Rates!$B:$B,MATCH(C10,Rates!$A:$A,0)),"N/A") -> 0.77738 | K10: =IF(Holdings[[#This Row],[Is USD]]="No",Holdings[[#This Row],[Buy Price]]*Holdings[[#This Row],[Qty]],Holdings[[#This Row],[US Price]]/Holdings[[#This Row],[AUD > US exc.]]) -> 9681.25 | L10: =IF(Holdings[[#This Row],[Is USD]]="Yes",Holdings[[#This Row],[Buy Price]]*Holdings[[#This Row],[Qty]],"")
A11: ASX:VTS_1 | B11: Vanguard US Total Market Shares Index ETF | C11: 44204 | D11: Gabriel | E11: Stock | F11: ASX:VTS | G11: No | H11: 29 | I11: 255.38 | J11: =IFERROR(INDEX(Rates!$B:$B,MATCH(C11,Rates!$A:$A,0)),"N/A") -> 0.77738 | K11: =IF(Holdings[[#This Row],[Is USD]]="No",Holdings[[#This Row],[Buy Price]]*Holdings[[#This Row],[Qty]],Holdings[[#This Row],[US Price]]/Holdings[[#This Row],[AUD > US exc.]]) -> 7406.02 | L11: =IF(Holdings[[#This Row],[Is USD]]="Yes",Holdings[[#This Row],[Buy Price]]*Holdings[[#This Row],[Qty]],"")
A12: BTCAUD_1 | B12: Bitcoin (AUD) | C12: 44538 | D12: Gabriel | E12: Stock | F12: BTCAUD | G12: No | H12: 0.07234 | I12: 69214 | J12: =IFERROR(INDEX(Rates!$B:$B,MATCH(C12,Rates!$A:$A,0)),"N/A") -> 0.71328 | K12: =IF(Holdings[[#This Row],[Is USD]]="No",Holdings[[#This Row],[Buy Price]]*Holdings[[#This Row],[Qty]],Holdings[[#This Row],[US Price]]/Holdings[[#This Row],[AUD > US exc.]]) -> 5006.9408 | L12: =IF(Holdings[[#This Row],[Is USD]]="Yes",Holdings[[#This Row],[Buy Price]]*Holdings[[#This Row],[Qty]],"")
A13: CRM_1 | B13: Salesforce Inc. | C13: 44230 | D13: Gabriel | E13: Stock | F13: CRM | G13: Yes | H13: 27.7088 | I13: 235 | J13: =IFERROR(INDEX(Rates!$B:$B,MATCH(C13,Rates!$A:$A,0)),"N/A") -> 0.76149 | K13: =IF(Holdings[[#This Row],[Is USD]]="No",Holdings[[#This Row],[Buy Price]]*Holdings[[#This Row],[Qty]],Holdings[[#This Row],[US Price]]/Holdings[[#This Row],[AUD > US exc.]]) -> 8551.088 | L13: =IF(Holdings[[#This Row],[Is USD]]="Yes",Holdings[[#This Row],[Buy Price]]*Holdings[[#This Row],[Qty]],"") -> 6511.568
... A20: TSLA_2 | B20: Tesla Inc. | C20: 44116 | D20: Gabriel | E20: Stock | F20: TSLA | G20: Yes | H20: 57.31 | I20: 140.13 | J20: =IFERROR(INDEX(Rates!$B:$B,MATCH(C20,Rates!$A:$A,0)),"N/A") -> 0.72134 | K20: =IF(Holdings[[#This Row],[Is USD]]="No",Holdings[[#This Row],[Buy Price]]*Holdings[[#This Row],[Qty]],Holdings[[#This Row],[US Price]]/Holdings[[#This Row],[AUD > US exc.]]) -> 11133.239 | L20: =IF(Holdings[[#This Row],[Is USD]]="Yes",Holdings[[#This Row],[Buy Price]]*Holdings[[#This Row],[Qty]],"") -> 8030.8503

Sheet Rates
A1: Date | B1: AUD → USD Rate
A2: 46120 | B2: 0.70565
A3: 46119 | B3: 0.69349
A4: 46114 | B4: 0.6872
A5: 46113 | B5: 0.69537
A6: 46112 | B6: 0.68879
A7: 46111 | B7: 0.68602
A8: 46108 | B8: 0.68836
A9: 46107 | B9: 0.69125
A10: 46106 | B10: 0.69634
A11: 46105 | B11: 0.69493
A12: 46104 | B12: 0.70198
A13: 46101 | B13: 0.70668
... A1219: 44105 | B1219: 0.72014

Sheet Stock Prices
A1: Date | B1: Ticker | C1: USD Price | D1: AUD Price | E1: Modified On
A2: 46121 | B2: AAPL | C2: 260.49 | D2: =IFERROR(C2/INDEX(Rates!$B:$B,MATCH(A2,Rates!$A:$A,0)),"") | E2: 46122.606
A3: 46121 | B3: AMZN | C3: 233.65 | D3: =IFERROR(C3/INDEX(Rates!$B:$B,MATCH(A3,Rates!$A:$A,0)),"") | E3: 46122.606
A4: 46121 | B4: ARKK | C4: 68.92 | D4: =IFERROR(C4/INDEX(Rates!$B:$B,MATCH(A4,Rates!$A:$A,0)),"") | E4: 46122.606
A5: 46121 | B5: CRM | C5: 170.85 | D5: =IFERROR(C5/INDEX(Rates!$B:$B,MATCH(A5,Rates!$A:$A,0)),"") | E5: 46122.606
A6: 46121 | B6: DIS | C6: 99.79 | D6: =IFERROR(C6/INDEX(Rates!$B:$B,MATCH(A6,Rates!$A:$A,0)),"") | E6: 46122.606
A7: 46121 | B7: FDX | C7: 377 | D7: =IFERROR(C7/INDEX(Rates!$B:$B,MATCH(A7,Rates!$A:$A,0)),"") | E7: 46122.606
A8: 46121 | B8: MSFT | C8: 373.07 | D8: =IFERROR(C8/INDEX(Rates!$B:$B,MATCH(A8,Rates!$A:$A,0)),"") | E8: 46122.606
A9: 46121 | B9: NIO | C9: 6.07 | D9: =IFERROR(C9/INDEX(Rates!$B:$B,MATCH(A9,Rates!$A:$A,0)),"") | E9: 46122.606
A10: 46121 | B10: TSLA | C10: 345.62 | D10: =IFERROR(C10/INDEX(Rates!$B:$B,MATCH(A10,Rates!$A:$A,0)),"") | E10: 46122.606
A11: 46120 | B11: AAPL | C11: 258.9 | D11: =IFERROR(C11/INDEX(Rates!$B:$B,MATCH(A11,Rates!$A:$A,0)),"") -> 366.89577 | E11: 46122.606
A12: 46120 | B12: AMZN | C12: 221.25 | D12: =IFERROR(C12/INDEX(Rates!$B:$B,MATCH(A12,Rates!$A:$A,0)),"") -> 313.54071 | E12: 46122.606
A13: 46120 | B13: ARKK | C13: 70.36 | D13: =IFERROR(C13/INDEX(Rates!$B:$B,MATCH(A13,Rates!$A:$A,0)),"") -> 99.709488 | E13: 46122.606
... A163: 46097 | B163: TSLA | C163: 395.56 | D163: =IFERROR(C163/INDEX(Rates!$B:$B,MATCH(A163,Rates!$A:$A,0)),"") -> 560.77575 | E163: 46122.606
A164: 46094 | B164: AMZN | C164: 207.67 | D164: =IFERROR(C164/INDEX(Rates!$B:$B,MATCH(A164,Rates!$A:$A,0)),"") -> 294.83921
A165: 46094 | B165: CRM | C165: 192.83 | D165: =IFERROR(C165/INDEX(Rates!$B:$B,MATCH(A165,Rates!$A:$A,0)),"") -> 273.77014
A166: 46094 | B166: DIS | C166: 99.29 | D166: =IFERROR(C166/INDEX(Rates!$B:$B,MATCH(A166,Rates!$A:$A,0)),"") -> 140.96685
A167: 46094 | B167: FDX | C167: 351.68 | D167: =IFERROR(C167/INDEX(Rates!$B:$B,MATCH(A167,Rates!$A:$A,0)),"") -> 499.29722
A168: 46094 | B168: MSFT | C168: 395.55 | D168: =IFERROR(C168/INDEX(Rates!$B:$B,MATCH(A168,Rates!$A:$A,0)),"") -> 561.5816
A169: 46094 | B169: NIO | C169: 5.86 | D169: =IFERROR(C169/INDEX(Rates!$B:$B,MATCH(A169,Rates!$A:$A,0)),"") -> 8.3197274
A170: 46094 | B170: TSLA | C170: 391.2 | D170: =IFERROR(C170/INDEX(Rates!$B:$B,MATCH(A170,Rates!$A:$A,0)),"") -> 555.40569
A171: 46094 | B171: ASXNDQ | D171: 51.26
A172: 46094 | B172: ASX:VAS | D172: 107.56
A173: 46094 | B173: ASX:VEU | D173: 107.6
A174: 46094 | B174: ASX:VTS | D174: 465.47
A175: 46094 | B175: ASX:NDQ | D175: 51.26
A176: 46094 | B176: AAPL | C176: 250.12 | D176: =IFERROR(C194/INDEX(Rates!$B:$B,MATCH(A194,Rates!$A:$A,0)),"") -> 141.08516 | E176: 46096.602
A177: 46094 | B177: ARKK | C177: 70.25 | D177: =IFERROR(C197/INDEX(Rates!$B:$B,MATCH(A197,Rates!$A:$A,0)),"") -> 7.6492798 | E177: 46096.613
A178: 46093 | B178: AMZN | C178: 209.53 | D178: =IFERROR(C180/INDEX(Rates!$B:$B,MATCH(A180,Rates!$A:$A,0)),"") -> 139.41
A179: 46093 | B179: CRM | C179: 199.28 | D179: =IFERROR(C181/INDEX(Rates!$B:$B,MATCH(A181,Rates!$A:$A,0)),"") -> 495.12072
A180: 46093 | B180: DIS | C180: 99.43 | D180: =IFERROR(C182/INDEX(Rates!$B:$B,MATCH(A182,Rates!$A:$A,0)),"") -> 563.44466
A181: 46093 | B181: FDX | C181: 353.13 | D181: =IFERROR(C183/INDEX(Rates!$B:$B,MATCH(A183,Rates!$A:$A,0)),"") -> 7.7816102
A182: 46093 | B182: MSFT | C182: 401.86 | D182: =IFERROR(C184/INDEX(Rates!$B:$B,MATCH(A184,Rates!$A:$A,0)),"") -> 553.84033
A183: 46093 | B183: NIO | C183: 5.55 | D183: =IFERROR(C185/INDEX(Rates!$B:$B,MATCH(A185,Rates!$A:$A,0)),"") -> 0
A184: 46093 | B184: TSLA | C184: 395.01 | D184: =IFERROR(C186/INDEX(Rates!$B:$B,MATCH(A186,Rates!$A:$A,0)),"") -> 0
A185: 46093 | B185: ASXNDQ | D185: 51.1
A186: 46093 | B186: ASX:VAS | D186: 107.76
A187: 46093 | B187: ASX:VEU | D187: 106.98
A188: 46093 | B188: ASX:VTS | D188: 462.83
A189: 46093 | B189: ASX:NDQ | D189: 51.1
...

Sheet Portfolio Tracking
A1: Date | B1: Ticker ID | C1: Ticker | D1: Qty | E1: USD Unit Price | F1: AUD Unit Price | G1: USD Total Price | H1: AUD Total Price | I1: Owner
A2: 44116 | B2: AAPL_1 | C2: AAPL | D2: 83.4307 | E2: 124.4 | G2: 10378.779 | H2: 14388.193 | I2: Gabriel
A3: 44116 | B3: AMZN_2 | C3: AMZN | D3: 63.36 | E3: 172.15 | G3: 10907.424 | H3: 15121.058 | I3: Gabriel
A4: 44116 | B4: MSFT_1 | C4: MSFT | D4: 33.1788 | E4: 221.4 | G4: 7345.7863 | H4: 10183.528 | I4: Gabriel
A5: 44116 | B5: TSLA_2 | C5: TSLA | D5: 57.31 | E5: 147.43 | G5: 8449.2133 | H5: 11713.219 | I5: Gabriel
A6: 44123 | B6: AAPL_1 | C6: AAPL | D6: 83.4307 | E6: 115.98 | G6: 9676.2926 | H6: 13609.222 | I6: Gabriel
A7: 44123 | B7: AMZN_2 | C7: AMZN | D7: 63.36 | E7: 160.36 | G7: 10160.41 | H7: 14290.108 | I7: Gabriel
A8: 44123 | B8: MSFT_1 | C8: MSFT | D8: 33.1788 | E8: 214.22 | G8: 7107.5625 | H8: 9996.4312 | I8: Gabriel
A9: 44123 | B9: TSLA_2 | C9: TSLA | D9: 57.31 | E9: 143.61 | G9: 8230.2891 | H9: 11575.49 | I9: Gabriel
A10: 44130 | B10: AAPL_1 | C10: AAPL | D10: 83.4307 | E10: 115.05 | G10: 9598.702 | H10: 13475.078 | I10: Gabriel
A11: 44130 | B11: AMZN_2 | C11: AMZN | D11: 63.36 | E11: 160.35 | G11: 10159.776 | H11: 14262.738 | I11: Gabriel
A12: 44130 | B12: MSFT_1 | C12: MSFT | D12: 33.1788 | E12: 210.08 | G12: 6970.2023 | H12: 9785.0748 | I12: Gabriel
A13: 44130 | B13: TSLA_2 | C13: TSLA | D13: 57.31 | E13: 140.09 | G13: 8028.5579 | H13: 11270.841 | I13: Gabriel
... A55: 44207 | B55: AMZN_2 | C55: AMZN | D55: 63.36 | E55: 155.71 | G55: 9865.7856 | H55: 12802.068 | I55: Gabriel
A56: 44207 | B56: ASX:NDQ_2 | C56: ASX:NDQ | D56: 258 | F56: 28.04 | H56: 7234.32 | I56: Gabriel
A57: 44207 | B57: ASX:VAS_1 | C57: ASX:VAS | D57: 178 | F57: 85.45 | H57: 15210.1 | I57: Gabriel
A58: 44207 | B58: ASX:VEU_2 | C58: ASX:VEU | D58: 125 | F58: 78.44 | H58: 9805 | I58: Gabriel
A59: 44207 | B59: ASX:VTS_1 | C59: ASX:VTS | D59: 29 | F59: 257.26 | H59: 7460.54 | I59: Gabriel
A60: 44207 | B60: MSFT_1 | C60: MSFT | D60: 33.1788 | E60: 217.49 | G60: 7216.0572 | H60: 9363.72 | I60: Gabriel
A61: 44207 | B61: TSLA_2 | C61: TSLA | D61: 57.31 | E61: 270.4 | G61: 15496.624 | H61: 20108.772 | I61: Gabriel
A62: 44214 | B62: AAPL_1 | C62: AAPL | D62: 83.4307 | E62: 127.83 | G62: 10664.946 | H62: 13897.869 | I62: Gabriel
A63: 44214 | B63: AMZN_2 | C63: AMZN | D63: 63.36 | E63: 156.04 | G63: 9886.6944 | H63: 12883.701 | I63: Gabriel
A64: 44214 | B64: ASX:NDQ_2 | C64: ASX:NDQ | D64: 258 | F64: 27.5 | H64: 7095 | I64: Gabriel
A65: 44214 | B65: ASX:VAS_1 | C65: ASX:VAS | D65: 178 | F65: 84.96 | H65: 15122.88 | I65: Gabriel
A66: 44214 | B66: ASX:VEU_2 | C66: ASX:VEU | D66: 125 | F66: 78.09 | H66: 9761.25 | I66: Gabriel
A67: 44214 | B67: ASX:VTS_1 | C67: ASX:VTS | D67: 29 | F67: 255.91 | H67: 7421.39 | I67: Gabriel
A68: 44214 | B68: MSFT_1 | C68: MSFT | D68: 33.1788 | E68: 216.44 | G68: 7181.2195 | H68: 9358.1009 | I68: Gabriel
A69: 44214 | B69: TSLA_2 | C69: TSLA | D69: 57.31 | E69: 281.52 | G69: 16133.911 | H69: 21024.67 | I69: Gabriel
A70: 44221 | B70: AAPL_1 | C70: AAPL | D70: 83.4307 | E70: 142.92 | G70: 11923.916 | H70: 15432.892 | I70: Gabriel
A71: 44221 | B71: AMZN_2 | C71: AMZN | D71: 63.36 | E71: 164.7 | G71: 10435.392 | H71: 13506.325 | I71: Gabriel
A72: 44221 | B72: ASX:NDQ_2 | C72: ASX:NDQ | D72: 258 | F72: 28.8 | H72: 7430.4 | I72: Gabriel
A73: 44221 | B73: ASX:VAS_1 | C73: ASX:VAS | D73: 178 | F73: 87.1 | H73: 15503.8 | I73: Gabriel
A74: 44221 | B74: ASX:VEU_2 | C74: ASX:VEU | D74: 125 | F74: 79.43 | H74: 9928.75 | I74: Gabriel
A75: 44221 | B75: ASX:VTS_1 | C75: ASX:VTS | D75: 29 | F75: 260.6 | H75: 7557.4 | I75: Gabriel
A76: 44221 | B76: MSFT_1 | C76: MSFT | D76: 33.1788 | E76: 229.53 | G76: 7615.53 | H76: 9856.6325 | I76: Gabriel
A77: 44221 | B77: TSLA_2 | C77: TSLA | D77: 57.31 | E77: 293.6 | G77: 16826.216 | H77: 21777.845 | I77: Gabriel
A78: 44228 | B78: AAPL_1 | C78: AAPL | D78: 83.4307 | E78: 134.14 | G78: 11191.394 | H78: 14661.663 | I78: Gabriel
A79: 44228 | B79: AMZN_2 | C79: AMZN | D79: 63.36 | E79: 167.14 | G79: 10589.99 | H79: 13873.774 | I79: Gabriel
A80: 44228 | B80: ASX:NDQ_2 | C80: ASX:NDQ | D80: 258 | F80: 28.06 | H80: 7239.48 | I80: Gabriel
A81: 44228 | B81: ASX:VAS_1 | C81: ASX:VAS | D81: 178 | F81: 85.04 | H81: 15137.12 | I81: Gabriel
...

Sheet Pivot Table
B8: (empty) | C8: Ticker ID
B9: Row Labels | C9: CRM_1 | D9: Total Result
B10: CRM
B11: 44235
B12: 44242
B13: 44249
B14: 44256
B15: 44263
B16: 44270
B17: 44277
B18: 44284
B19: 44291
B20: 44298
B21: 44305
B22: 44312
... B276: 46090
B277: Total Result

Sheet PnL_Data
A1: Date | B1: Owner | C1: Ticker | D1: P&L AUD | E1: Portfolio Value AUD | F1: Cost Basis AUD
A2: 44116 | B2: Gabriel | C2: AAPL | D2: 525.1 | E2: 14388.19 | F2: 13863.09
A3: 44116 | B3: Gabriel | C3: AMZN | D3: 1257.82 | E3: 15121.06 | F3: 13863.24
A4: 44116 | B4: Gabriel | C4: MSFT | D4: 312.77 | E4: 10183.53 | F4: 9870.76
A5: 44116 | B5: Gabriel | C5: TSLA | D5: 579.98 | E5: 11713.22 | F5: 11133.24
A6: 44117 | B6: Gabriel | C6: AAPL | D6: 197.02 | E6: 14060.11 | F6: 13863.09
A7: 44117 | B7: Gabriel | C7: AMZN | D7: 1318.33 | E7: 15181.57 | F7: 13863.24
A8: 44117 | B8: Gabriel | C8: MSFT | D8: 419.16 | E8: 10289.91 | F8: 9870.76
A9: 44117 | B9: Gabriel | C9: TSLA | D9: 740.45 | E9: 11873.69 | F9: 11133.24
A10: 44118 | B10: Gabriel | C10: AAPL | D10: 230.22 | E10: 14093.31 | F10: 13863.09
A11: 44118 | B11: Gabriel | C11: AMZN | D11: 990.5 | E11: 14853.74 | F11: 13863.24
A12: 44118 | B12: Gabriel | C12: MSFT | D12: 343.3 | E12: 10214.06 | F12: 9870.76
A13: 44118 | B13: Gabriel | C13: TSLA | D13: 1150.27 | E13: 12283.51 | F13: 11133.24
... A18344: 46094 | B18344: Gabriel | C18344: ASX:VTS | D18344: 6092.61 | E18344: 13498.63 | F18344: 7406.02

Sheet Position
A1: Current Holdings — 14 April 2026
A3: Owner | B3: Ticker | C3: Type | D3: Qty | E3: Purchase Date | F3: Buy Price | G3: Current Price | H3: Current Value (AUD) | I3: Price Variation ($) | J3: Price Variation (%)
A4: Arina | B4: AMZN | C4: Stock | D4: 20 | E4: 44350 | F4: 160 | G4: 233.65 | H4: 6622.2632 | I4: =(G4*D4)-(F4*D4) -> 1473 | J4: =((G4*D4)-(F4*D4))/(F4*D4) -> 0.4603125
A5: Arina | B5: ARKK | C5: Stock | D5: 31.176929 | E5: 44300 | F5: 128.3 | G5: 68.92 | H5: 3045.0137 | I5: =(G5*D5)-(F5*D5) -> -1851.286 | J5: =((G5*D5)-(F5*D5))/(F5*D5) -> -0.46282151
A6: Arina | B6: ASX:NDQ | C6: Stock | D6: 233 | E6: 44322 | F6: 28.9 | G6: 51.26 | H6: 11943.58 | I6: =(G6*D6)-(F6*D6) -> 5209.88 | J6: =((G6*D6)-(F6*D6))/(F6*D6) -> 0.77370242
A7: Arina | B7: ASX:VEU | C7: Stock | D7: 48 | E7: 44322 | F7: 80.92 | G7: 107.6 | H7: 5164.8 | I7: =(G7*D7)-(F7*D7) -> 1280.64 | J7: =((G7*D7)-(F7*D7))/(F7*D7) -> 0.32970835
A8: Arina | B8: DIS | C8: Stock | D8: 21.350947 | E8: 44298 | F8: 187.35 | G8: 99.79 | H8: 3019.3595 | I8: =(G8*D8)-(F8*D8) -> -1869.4889 | J8: =((G8*D8)-(F8*D8))/(F8*D8) -> -0.46736056
A9: Arina | B9: FDX | C9: Stock | D9: 13.630454 | E9: 44244 | F9: 264 | G9: 377 | H9: 7282.1954 | I9: =(G9*D9)-(F9*D9) -> 1540.2413 | J9: =((G9*D9)-(F9*D9))/(F9*D9) -> 0.4280303
A10: Arina | B10: NIO | C10: Stock | D10: 66.334992 | E10: 44244 | F10: 60.3 | G10: 6.07 | H10: 570.61348 | I10: =(G10*D10)-(F10*D10) -> -3597.3466 | J10: =((G10*D10)-(F10*D10))/(F10*D10) -> -0.89933665
A11: Arina | B11: TSLA | C11: Stock | D11: 120.9 | E11: 44298 | F11: 297.17 | G11: 345.62 | H11: 59215.557 | I11: =(G11*D11)-(F11*D11) -> 5857.605 | J11: =((G11*D11)-(F11*D11))/(F11*D11) -> 0.16303799
A12: Gabriel | B12: AAPL | C12: Stock | D12: 83.4307 | E12: 44116 | F12: 119.86 | G12: 260.49 | H12: 30798.36 | I12: =(G12*D12)-(F12*D12) -> 11732.859 | J12: =((G12*D12)-(F12*D12))/(F12*D12) -> 1.1732855
A13: Gabriel | B13: AMZN | C13: Stock | D13: 63.36 | E13: 44116 | F13: 157.83 | G13: 233.65 | H13: 20979.33 | I13: =(G13*D13)-(F13*D13) -> 4803.9552 | J13: =((G13*D13)-(F13*D13))/(F13*D13) -> 0.48039029
A14: Gabriel | B14: ASX:NDQ | C14: Stock | D14: 258 | E14: 44204 | F14: 27.6 | G14: 51.26 | H14: 13225.08 | I14: =(G14*D14)-(F14*D14) -> 6104.28 | J14: =((G14*D14)-(F14*D14))/(F14*D14) -> 0.85724638
A15: Gabriel | B15: ASX:VAS | C15: Stock | D15: 178 | E15: 44204 | F15: 85.91 | G15: 107.56 | H15: 19145.68 | I15: =(G15*D15)-(F15*D15) -> 3853.7 | J15: =((G15*D15)-(F15*D15))/(F15*D15) -> 0.25200792
... A17: Gabriel | B17: ASX:VTS | C17: Stock | D17: 29 | E17: 44204 | F17: 255.38 | G17: 465.47 | H17: 13498.63 | I17: =(G17*D17)-(F17*D17) -> 6092.61 | J17: =((G17*D17)-(F17*D17))/(F17*D17) -> 0.82265643
A18: Gabriel | B18: BTCAUD | C18: Stock | D18: 0.07234 | E18: 44538 | F18: 69214 | I18: =(G18*D18)-(F18*D18) -> -5006.9408 | J18: =((G18*D18)-(F18*D18))/(F18*D18) -> -1
A19: Gabriel | B19: CRM | C19: Stock | D19: 27.7088 | E19: 44230 | F19: 235 | G19: 170.85 | H19: 6708.777 | I19: =(G19*D19)-(F19*D19) -> -1777.5195 | J19: =((G19*D19)-(F19*D19))/(F19*D19) -> -0.27297872
A20: Gabriel | B20: ETHAUD | C20: Stock | D20: 0.89 | E20: 44538 | F20: 5571 | I20: =(G20*D20)-(F20*D20) -> -4958.19 | J20: =((G20*D20)-(F20*D20))/(F20*D20) -> -1
A21: Gabriel | B21: MSFT | C21: Stock | D21: 33.1788 | E21: 44116 | F21: 214.6 | G21: 373.07 | H21: 17541.295 | I21: =(G21*D21)-(F21*D21) -> 5257.8444 | J21: =((G21*D21)-(F21*D21))/(F21*D21) -> 0.73844362
A22: Gabriel | B22: TSLA | C22: Stock | D22: 57.31 | E22: 44116 | F22: 140.13 | G22: 345.62 | H22: 28069.839 | I22: =(G22*D22)-(F22*D22) -> 11776.632 | J22: =((G22*D22)-(F22*D22))/(F22*D22) -> 1.466424
